Workbook

Sheet Cliente
A1: Id | B1: Nome | C1: CPF-CNPJ | D1: Cidade UF | E1: Anotações Cliente | F1: Valor Total | G1: Valor Pago | H1: Valor Pendente
A2: a5d4b2e5 | B2: Adailton | F2: =SUMIFS(PedidodeVenda!E:E,PedidodeVenda!D:D,B:B) -> 0 | G2: =SUMIFS(PedidodeVenda!F:F,PedidodeVenda!D:D,B:B) -> 0 | H2: =F2-G2 -> 0
A3: a5d4b2e6 | B3: Alianca | F3: =SUMIFS(PedidodeVenda!E:E,PedidodeVenda!D:D,B:B) -> 0 | G3: =SUMIFS(PedidodeVenda!F:F,PedidodeVenda!D:D,B:B) -> 0 | H3: =F3-G3 -> 0
A4: a5d4b2e7 | B4: Alipio Gomes da Costa | C4: 211.898.624-68 | D4: São Bento da Una/PE | F4: =SUMIFS(PedidodeVenda!E:E,PedidodeVenda!D:D,B:B) -> 0 | G4: =SUMIFS(PedidodeVenda!F:F,PedidodeVenda!D:D,B:B) -> 0 | H4: =F4-G4 -> 0
A5: a5d4b2e36 | B5: André Corretor | F5: =SUMIFS(PedidodeVenda!E:E,PedidodeVenda!D:D,B:B) -> 54131.19 | G5: =SUMIFS(PedidodeVenda!F:F,PedidodeVenda!D:D,B:B) -> 54131.19 | H5: =F5-G5 -> 0
A6: a5d4b2e20 | B6: Cajazeirinhas | F6: =SUMIFS(PedidodeVenda!E:E,PedidodeVenda!D:D,B:B) -> 0 | G6: =SUMIFS(PedidodeVenda!F:F,PedidodeVenda!D:D,B:B) -> 0 | H6: =F6-G6 -> 0
A7: a5d4b2e21 | B7: Caruaru J2 | F7: =SUMIFS(PedidodeVenda!E:E,PedidodeVenda!D:D,B:B) -> 0 | G7: =SUMIFS(PedidodeVenda!F:F,PedidodeVenda!D:D,B:B) -> 0 | H7: =F7-G7 -> 0
A8: a5d4b2e22 | B8: Clodoaldo Corretor | F8: =SUMIFS(PedidodeVenda!E:E,PedidodeVenda!D:D,B:B) -> 9143744.8 | G8: =SUMIFS(PedidodeVenda!F:F,PedidodeVenda!D:D,B:B) -> 9113073.4 | H8: =F8-G8 -> 30671.34
A9: a5d4b2e23 | B9: Cooperflores | F9: =SUMIFS(PedidodeVenda!E:E,PedidodeVenda!D:D,B:B) -> 363744 | G9: =SUMIFS(PedidodeVenda!F:F,PedidodeVenda!D:D,B:B) -> 363744 | H9: =F9-G9 -> 0
A10: a5d4b2e24 | B10: Diego Atacadao Racao | F10: =SUMIFS(PedidodeVenda!E:E,PedidodeVenda!D:D,B:B) -> 4263252 | G10: =SUMIFS(PedidodeVenda!F:F,PedidodeVenda!D:D,B:B) -> 4263252 | H10: =F10-G10 -> 0
A11: a5d4b2e25 | B11: Ducampo Campina | F11: =SUMIFS(PedidodeVenda!E:E,PedidodeVenda!D:D,B:B) -> 0 | G11: =SUMIFS(PedidodeVenda!F:F,PedidodeVenda!D:D,B:B) -> 0 | H11: =F11-G11 -> 0
A12: a5d4b2e26 | B12: Fernando Vilela | F12: =SUMIFS(PedidodeVenda!E:E,PedidodeVenda!D:D,B:B) -> 0 | G12: =SUMIFS(PedidodeVenda!F:F,PedidodeVenda!D:D,B:B) -> 0 | H12: =F12-G12 -> 0
A13: a5d4b2e28 | B13: Frango Favorito Ltda | C13: 24.959.078/0023-01 | D13: Belo Jardim/PE | F13: =SUMIFS(PedidodeVenda!E:E,PedidodeVenda!D:D,B:B) -> 0 | G13: =SUMIFS(PedidodeVenda!F:F,PedidodeVenda!D:D,B:B) -> 0 | H13: =F13-G13 -> 0
A14: a5d4b2e29 | B14: Granja Canaa | F14: =SUMIFS(PedidodeVenda!E:E,PedidodeVenda!D:D,B:B) -> 2440901.7 | G14: =SUMIFS(PedidodeVenda!F:F,PedidodeVenda!D:D,B:B) -> 2440901.7 | H14: =F14-G14 -> 0
A15: a5d4b2e30 | B15: Granja Kumamoto | F15: =SUMIFS(PedidodeVenda!E:E,PedidodeVenda!D:D,B:B) -> 485105.74 | G15: =SUMIFS(PedidodeVenda!F:F,PedidodeVenda!D:D,B:B) -> 485105.74 | H15: =F15-G15 -> 0
A16: a5d4b2e31 | B16: Guaraves | F16: =SUMIFS(PedidodeVenda!E:E,PedidodeVenda!D:D,B:B) -> 2927598.8 | G16: =SUMIFS(PedidodeVenda!F:F,PedidodeVenda!D:D,B:B) -> 2927598.8 | H16: =F16-G16 -> 0
A17: a5d4b2e32 | B17: Japones | F17: =SUMIFS(PedidodeVenda!E:E,PedidodeVenda!D:D,B:B) -> 1220579.3 | G17: =SUMIFS(PedidodeVenda!F:F,PedidodeVenda!D:D,B:B) -> 1220579.3 | H17: =F17-G17 -> -2.3283064e-10
A18: a5d4b2e33 | B18: Kenichi Iwata | C18: 084.455.084-15 | D18: Tejucupapo/PE | F18: =SUMIFS(PedidodeVenda!E:E,PedidodeVenda!D:D,B:B) -> 0 | G18: =SUMIFS(PedidodeVenda!F:F,PedidodeVenda!D:D,B:B) -> 0 | H18: =F18-G18 -> 0
A19: a5d4b2e34 | B19: Matildes | F19: =SUMIFS(PedidodeVenda!E:E,PedidodeVenda!D:D,B:B) -> 0 | G19: =SUMIFS(PedidodeVenda!F:F,PedidodeVenda!D:D,B:B) -> 0 | H19: =F19-G19 -> 0
A20: a5d4b2e35 | B20: Michael Campina Grande | F20: =SUMIFS(PedidodeVenda!E:E,PedidodeVenda!D:D,B:B) -> 3358421.9 | G20: =SUMIFS(PedidodeVenda!F:F,PedidodeVenda!D:D,B:B) -> 3358421.9 | H20: =F20-G20 -> 0
A21: a5d4b2e37 | B21: Natto Alimentos | C21: 01.682.695/0001-00 | D21: Garanhuns/PE | F21: =SUMIFS(PedidodeVenda!E:E,PedidodeVenda!D:D,B:B) -> 8538483.8 | G21: =SUMIFS(PedidodeVenda!F:F,PedidodeVenda!D:D,B:B) -> 8537819.7 | H21: =F21-G21 -> 664.12
A22: a5d4b2e38 | B22: Ovos Sao Tome | F22: =SUMIFS(PedidodeVenda!E:E,PedidodeVenda!D:D,B:B) -> 1562176.2 | G22: =SUMIFS(PedidodeVenda!F:F,PedidodeVenda!D:D,B:B) -> 1456011.2 | H22: =F22-G22 -> 106165
A23: a5d4b2e39 | B23: Pesqueira | F23: =SUMIFS(PedidodeVenda!E:E,PedidodeVenda!D:D,B:B) -> 0 | G23: =SUMIFS(PedidodeVenda!F:F,PedidodeVenda!D:D,B:B) -> 0 | H23: =F23-G23 -> 0
A24: a5d4b2e40 | B24: Rei Do Ouro | F24: =SUMIFS(PedidodeVenda!E:E,PedidodeVenda!D:D,B:B) -> 1670988 | G24: =SUMIFS(PedidodeVenda!F:F,PedidodeVenda!D:D,B:B) -> 1670988 | H24: =F24-G24 -> 0
A25: a5d4b2e41 | B25: Reinaldo | F25: =SUMIFS(PedidodeVenda!E:E,PedidodeVenda!D:D,B:B) -> 489282.02 | G25: =SUMIFS(PedidodeVenda!F:F,PedidodeVenda!D:D,B:B) -> 489282.02 | H25: =F25-G25 -> 0
A26: a5d4b2e42 | B26: Rildo Roque Ferraz | C26: 22.381.240/0001-16 | D26: Sao Bento do Una/PE | F26: =SUMIFS(PedidodeVenda!E:E,PedidodeVenda!D:D,B:B) -> 2321404 | G26: =SUMIFS(PedidodeVenda!F:F,PedidodeVenda!D:D,B:B) -> 2319272.2 | H26: =F26-G26 -> 2131.83
A27: a5d4b2e43 | B27: Rural Log Pedro Falcao | F27: =SUMIFS(PedidodeVenda!E:E,PedidodeVenda!D:D,B:B) -> 0 | G27: =SUMIFS(PedidodeVenda!F:F,PedidodeVenda!D:D,B:B) -> 0 | H27: =F27-G27 -> 0
A28: a5d4b2e44 | B28: Sao Bento Branco | F28: =SUMIFS(PedidodeVenda!E:E,PedidodeVenda!D:D,B:B) -> 0 | G28: =SUMIFS(PedidodeVenda!F:F,PedidodeVenda!D:D,B:B) -> 0 | H28: =F28-G28 -> 0
A29: a5d4b2e46 | B29: São Braz S/A Industria E Comercio De Alimentos | C29: 08.811.226/0001-84 | D29: Cabedelo/PB | F29: =SUMIFS(PedidodeVenda!E:E,PedidodeVenda!D:D,B:B) -> 32158026 | G29: =SUMIFS(PedidodeVenda!F:F,PedidodeVenda!D:D,B:B) -> 31678764 | H29: =F29-G29 -> 479261.64
A30: a5d4b2e47 | B30: Sr. Pedro São Bento | F30: =SUMIFS(PedidodeVenda!E:E,PedidodeVenda!D:D,B:B) -> 0 | G30: =SUMIFS(PedidodeVenda!F:F,PedidodeVenda!D:D,B:B) -> 0 | H30: =F30-G30 -> 0
A31: a5d4b2e48 | B31: Sr. Pedro Vitoria | F31: =SUMIFS(PedidodeVenda!E:E,PedidodeVenda!D:D,B:B) -> 1103947.1 | G31: =SUMIFS(PedidodeVenda!F:F,PedidodeVenda!D:D,B:B) -> 1103947.1 | H31: =F31-G31 -> 0
A32: a5d4b2e49 | B32: Thiago Garanhuns | D32: Garanhuns/PE | F32: =SUMIFS(PedidodeVenda!E:E,PedidodeVenda!D:D,B:B) -> 703352.51 | G32: =SUMIFS(PedidodeVenda!F:F,PedidodeVenda!D:D,B:B) -> 703352.51 | H32: =F32-G32 -> 0
A33: a5d4b2e52 | B33: Vitamilho Alimentos LTDA | C33: 00.686.452/0001-79 | D33: Garanhuns/PE | F33: =SUMIFS(PedidodeVenda!E:E,PedidodeVenda!D:D,B:B) -> 5652731.7 | G33: =SUMIFS(PedidodeVenda!F:F,PedidodeVenda!D:D,B:B) -> 5652731.7 | H33: =F33-G33 -> 0
A34: ded4bf47 | B34: Ana Maria Laroche | D34: Paulista/PE | F34: =SUMIFS(PedidodeVenda!E:E,PedidodeVenda!D:D,B:B) -> 2359757.7 | G34: =SUMIFS(PedidodeVenda!F:F,PedidodeVenda!D:D,B:B) -> 2258453.6 | H34: =F34-G34 -> 101304.07
A35: 3f5ae7e1 | B35: André Timbauba | D35: Timbauba/PE | F35: =SUMIFS(PedidodeVenda!E:E,PedidodeVenda!D:D,B:B) -> 940078.7 | G35: =SUMIFS(PedidodeVenda!F:F,PedidodeVenda!D:D,B:B) -> 940078.7 | H35: =F35-G35 -> 0
A36: fc3e3b63 | B36: André Canguaretama | D36: Canguaretama/RN | F36: =SUMIFS(PedidodeVenda!E:E,PedidodeVenda!D:D,B:B) -> 192205.94 | G36: =SUMIFS(PedidodeVenda!F:F,PedidodeVenda!D:D,B:B) -> 192205.94 | H36: =F36-G36 -> 0
A37: 3b11ed5d | B37: Santa Cruz - RN | D37: Santa Cruz/RN | F37: =SUMIFS(PedidodeVenda!E:E,PedidodeVenda!D:D,B:B) -> 1095882.5 | G37: =SUMIFS(PedidodeVenda!F:F,PedidodeVenda!D:D,B:B) -> 1095882.5 | H37: =F37-G37 -> 0
A38: 96061475 | B38: Frei Damião | D38: Garanhuns/PE | F38: =SUMIFS(PedidodeVenda!E:E,PedidodeVenda!D:D,B:B) -> 2011585.4 | G38: =SUMIFS(PedidodeVenda!F:F,PedidodeVenda!D:D,B:B) -> 2010559 | H38: =F38-G38 -> 1026.4
A39: 38613a7e | B39: André Mamanguape | D39: Mamanguape/PB | F39: =SUMIFS(PedidodeVenda!E:E,PedidodeVenda!D:D,B:B) -> 495390.98 | G39: =SUMIFS(PedidodeVenda!F:F,PedidodeVenda!D:D,B:B) -> 495390.98 | H39: =F39-G39 -> 0
A40: 4540227f | B40: André Macaíbas | D40: Macaíbas/RN | F40: =SUMIFS(PedidodeVenda!E:E,PedidodeVenda!D:D,B:B) -> 1619564.1 | G40: =SUMIFS(PedidodeVenda!F:F,PedidodeVenda!D:D,B:B) -> 1619564.1 | H40: =F40-G40 -> 0
...

Sheet Produtor
A1: Id | B1: Nome | C1: CPF-CNPJ | D1: Cidade UF | E1: Valor Total | F1: Valor Pago | G1: Valor Pendente
A2: bce7e1da53 | B2: Adalberto Gloria | D2: Nossa Senhora da Glória/SE | E2: =SUMIFS(PedidodeCompra!F:F,PedidodeCompra!D:D,B:B) -> 0 | F2: =SUMIFS(PedidodeCompra!G:G,PedidodeCompra!D:D,B:B) -> 0 | G2: =E2-F2 -> 0
A3: bce7e1da51 | B3: Adriano Aquidaba | D3: Aquidabã/SE | E3: =SUMIFS(PedidodeCompra!F:F,PedidodeCompra!D:D,B:B) -> 0 | F3: =SUMIFS(PedidodeCompra!G:G,PedidodeCompra!D:D,B:B) -> 0 | G3: =E3-F3 -> 0
A4: bce7e1da08 | B4: Alan Plantec | D4: Nossa Senhora da Glória/SE | E4: =SUMIFS(PedidodeCompra!F:F,PedidodeCompra!D:D,B:B) -> 0 | F4: =SUMIFS(PedidodeCompra!G:G,PedidodeCompra!D:D,B:B) -> 0 | G4: =E4-F4 -> 0
A5: bce7e1da60 | B5: Alexandre | D5: Nossa Senhora da Glória/SE | E5: =SUMIFS(PedidodeCompra!F:F,PedidodeCompra!D:D,B:B) -> 0 | F5: =SUMIFS(PedidodeCompra!G:G,PedidodeCompra!D:D,B:B) -> 0 | G5: =E5-F5 -> 0
A6: bce7e1da04 | B6: Andre Aparecida | D6: Oeiras/MA | E6: =SUMIFS(PedidodeCompra!F:F,PedidodeCompra!D:D,B:B) -> 0 | F6: =SUMIFS(PedidodeCompra!G:G,PedidodeCompra!D:D,B:B) -> 0 | G6: =E6-F6 -> 0
A7: bce7e1da18 | B7: Bruno Emporio | D7: Nossa Senhora da Glória/SE | E7: =SUMIFS(PedidodeCompra!F:F,PedidodeCompra!D:D,B:B) -> 0 | F7: =SUMIFS(PedidodeCompra!G:G,PedidodeCompra!D:D,B:B) -> 0 | G7: =E7-F7 -> 0
A8: bce7e1da62 | B8: Carlos Japoata | D8: Japoatã/SE | E8: =SUMIFS(PedidodeCompra!F:F,PedidodeCompra!D:D,B:B) -> 0 | F8: =SUMIFS(PedidodeCompra!G:G,PedidodeCompra!D:D,B:B) -> 0 | G8: =E8-F8 -> 0
A9: bce7e1da27 | B9: Daniel Adustina | D9: Adustina /BA | E9: =SUMIFS(PedidodeCompra!F:F,PedidodeCompra!D:D,B:B) -> 0 | F9: =SUMIFS(PedidodeCompra!G:G,PedidodeCompra!D:D,B:B) -> 0 | G9: =E9-F9 -> 0
A10: bce7e1da35 | B10: Daniel Alagoas | D10: Batalha/AL | E10: =SUMIFS(PedidodeCompra!F:F,PedidodeCompra!D:D,B:B) -> 0 | F10: =SUMIFS(PedidodeCompra!G:G,PedidodeCompra!D:D,B:B) -> 0 | G10: =E10-F10 -> 0
A11: bce7e1da09 | B11: Diogo Sobral | E11: =SUMIFS(PedidodeCompra!F:F,PedidodeCompra!D:D,B:B) -> 0 | F11: =SUMIFS(PedidodeCompra!G:G,PedidodeCompra!D:D,B:B) -> 0 | G11: =E11-F11 -> 0
A12: bce7e1da30 | B12: Ecinho | E12: =SUMIFS(PedidodeCompra!F:F,PedidodeCompra!D:D,B:B) -> 0 | F12: =SUMIFS(PedidodeCompra!G:G,PedidodeCompra!D:D,B:B) -> 0 | G12: =E12-F12 -> 0
A13: bce7e1da26 | B13: Ednilson Balsas | D13: Balsas/MA | E13: =SUMIFS(PedidodeCompra!F:F,PedidodeCompra!D:D,B:B) -> 0 | F13: =SUMIFS(PedidodeCompra!G:G,PedidodeCompra!D:D,B:B) -> 0 | G13: =E13-F13 -> 0
A14: bce7e1da22 | B14: Eduardo | E14: =SUMIFS(PedidodeCompra!F:F,PedidodeCompra!D:D,B:B) -> 0 | F14: =SUMIFS(PedidodeCompra!G:G,PedidodeCompra!D:D,B:B) -> 0 | G14: =E14-F14 -> 0
A15: bce7e1da59 | B15: Elizeu | E15: =SUMIFS(PedidodeCompra!F:F,PedidodeCompra!D:D,B:B) -> 1507330.4 | F15: =SUMIFS(PedidodeCompra!G:G,PedidodeCompra!D:D,B:B) -> 1507330.4 | G15: =E15-F15 -> -2.3283064e-10
A16: bce7e1da05 | B16: Fabiano Balsas | D16: Balsas/MA | E16: =SUMIFS(PedidodeCompra!F:F,PedidodeCompra!D:D,B:B) -> 1759954.3 | F16: =SUMIFS(PedidodeCompra!G:G,PedidodeCompra!D:D,B:B) -> 1759954.3 | G16: =E16-F16 -> 0
A17: bce7e1da31 | B17: Francisco Benjamin | E17: =SUMIFS(PedidodeCompra!F:F,PedidodeCompra!D:D,B:B) -> 1655732.9 | F17: =SUMIFS(PedidodeCompra!G:G,PedidodeCompra!D:D,B:B) -> 1655732.9 | G17: =E17-F17 -> -2.3283064e-10
A18: bce7e1da25 | B18: Gabriel Balsas | E18: =SUMIFS(PedidodeCompra!F:F,PedidodeCompra!D:D,B:B) -> 0 | F18: =SUMIFS(PedidodeCompra!G:G,PedidodeCompra!D:D,B:B) -> 0 | G18: =E18-F18 -> 0
A19: bce7e1da20 | B19: Gastura | D19: Japoatã/SE | E19: =SUMIFS(PedidodeCompra!F:F,PedidodeCompra!D:D,B:B) -> 140646.44 | F19: =SUMIFS(PedidodeCompra!G:G,PedidodeCompra!D:D,B:B) -> 140646.44 | G19: =E19-F19 -> 0
A20: bce7e1da63 | B20: George | E20: =SUMIFS(PedidodeCompra!F:F,PedidodeCompra!D:D,B:B) -> 217203.5 | F20: =SUMIFS(PedidodeCompra!G:G,PedidodeCompra!D:D,B:B) -> 217203.5 | G20: =E20-F20 -> 0
A21: bce7e1da21 | B21: George Tocantins | E21: =SUMIFS(PedidodeCompra!F:F,PedidodeCompra!D:D,B:B) -> 99054.65 | F21: =SUMIFS(PedidodeCompra!G:G,PedidodeCompra!D:D,B:B) -> 99054.65 | G21: =E21-F21 -> 0
A22: bce7e1da41 | B22: Geraldo Japoata | D22: Japoatã/SE | E22: =SUMIFS(PedidodeCompra!F:F,PedidodeCompra!D:D,B:B) -> 0 | F22: =SUMIFS(PedidodeCompra!G:G,PedidodeCompra!D:D,B:B) -> 0 | G22: =E22-F22 -> 0
A23: bce7e1da14 | B23: Guilherme Balsas | E23: =SUMIFS(PedidodeCompra!F:F,PedidodeCompra!D:D,B:B) -> 2670874.9 | F23: =SUMIFS(PedidodeCompra!G:G,PedidodeCompra!D:D,B:B) -> 2670874.9 | G23: =E23-F23 -> 0
A24: bce7e1da42 | B24: Heder Suporte | D24: Nossa Senhora da Glória/SE | E24: =SUMIFS(PedidodeCompra!F:F,PedidodeCompra!D:D,B:B) -> 0 | F24: =SUMIFS(PedidodeCompra!G:G,PedidodeCompra!D:D,B:B) -> 0 | G24: =E24-F24 -> 0
A25: bce7e1da52 | B25: Jamisson Propria | D25: Própria /SE | E25: =SUMIFS(PedidodeCompra!F:F,PedidodeCompra!D:D,B:B) -> 0 | F25: =SUMIFS(PedidodeCompra!G:G,PedidodeCompra!D:D,B:B) -> 0 | G25: =E25-F25 -> 0
A26: bce7e1da43 | B26: Jr Dede | E26: =SUMIFS(PedidodeCompra!F:F,PedidodeCompra!D:D,B:B) -> 0 | F26: =SUMIFS(PedidodeCompra!G:G,PedidodeCompra!D:D,B:B) -> 0 | G26: =E26-F26 -> 0
A27: bce7e1da11 | B27: Jr Grao | E27: =SUMIFS(PedidodeCompra!F:F,PedidodeCompra!D:D,B:B) -> 958633.62 | F27: =SUMIFS(PedidodeCompra!G:G,PedidodeCompra!D:D,B:B) -> 958633.62 | G27: =E27-F27 -> 0
A28: bce7e1da29 | B28: Kelly Itabaianinha | E28: =SUMIFS(PedidodeCompra!F:F,PedidodeCompra!D:D,B:B) -> 1325394.7 | F28: =SUMIFS(PedidodeCompra!G:G,PedidodeCompra!D:D,B:B) -> 1325394.7 | G28: =E28-F28 -> 0
A29: bce7e1da06 | B29: Lucas Bom Jesus | E29: =SUMIFS(PedidodeCompra!F:F,PedidodeCompra!D:D,B:B) -> 0 | F29: =SUMIFS(PedidodeCompra!G:G,PedidodeCompra!D:D,B:B) -> 0 | G29: =E29-F29 -> 0
A30: bce7e1da03 | B30: Lucas Sobral | D30: Buriticupu/MA | E30: =SUMIFS(PedidodeCompra!F:F,PedidodeCompra!D:D,B:B) -> 3119590.3 | F30: =SUMIFS(PedidodeCompra!G:G,PedidodeCompra!D:D,B:B) -> 2824634.4 | G30: =E30-F30 -> 294955.91
A31: bce7e1da39 | B31: Luiz Eduardo Gordinho | E31: =SUMIFS(PedidodeCompra!F:F,PedidodeCompra!D:D,B:B) -> 0 | F31: =SUMIFS(PedidodeCompra!G:G,PedidodeCompra!D:D,B:B) -> 0 | G31: =E31-F31 -> 0
A32: bce7e1da34 | B32: Luiz Eduardo Magalhaes | E32: =SUMIFS(PedidodeCompra!F:F,PedidodeCompra!D:D,B:B) -> 0 | F32: =SUMIFS(PedidodeCompra!G:G,PedidodeCompra!D:D,B:B) -> 0 | G32: =E32-F32 -> 0
A33: bce7e1da50 | B33: Maicon Faz Capanema | E33: =SUMIFS(PedidodeCompra!F:F,PedidodeCompra!D:D,B:B) -> 0 | F33: =SUMIFS(PedidodeCompra!G:G,PedidodeCompra!D:D,B:B) -> 0 | G33: =E33-F33 -> 0
A34: bce7e1da54 | B34: Maicon Lem | E34: =SUMIFS(PedidodeCompra!F:F,PedidodeCompra!D:D,B:B) -> 0 | F34: =SUMIFS(PedidodeCompra!G:G,PedidodeCompra!D:D,B:B) -> 0 | G34: =E34-F34 -> 0
A35: bce7e1da12 | B35: Marconi Balsas | D35: Balsas /MA | E35: =SUMIFS(PedidodeCompra!F:F,PedidodeCompra!D:D,B:B) -> 3604251.7 | F35: =SUMIFS(PedidodeCompra!G:G,PedidodeCompra!D:D,B:B) -> 3603099.8 | G35: =E35-F35 -> 1151.93
A36: bce7e1da61 | B36: Marcos Roco Graccho | D36: Graccho Cardoso/SE | E36: =SUMIFS(PedidodeCompra!F:F,PedidodeCompra!D:D,B:B) -> 292740.7 | F36: =SUMIFS(PedidodeCompra!G:G,PedidodeCompra!D:D,B:B) -> 292740.7 | G36: =E36-F36 -> 0
A37: bce7e1da48 | B37: Marquinhos | E37: =SUMIFS(PedidodeCompra!F:F,PedidodeCompra!D:D,B:B) -> 272020 | F37: =SUMIFS(PedidodeCompra!G:G,PedidodeCompra!D:D,B:B) -> 272020 | G37: =E37-F37 -> 0
A38: bce7e1da36 | B38: Matheus Vilar | E38: =SUMIFS(PedidodeCompra!F:F,PedidodeCompra!D:D,B:B) -> 0 | F38: =SUMIFS(PedidodeCompra!G:G,PedidodeCompra!D:D,B:B) -> 0 | G38: =E38-F38 -> 0
A39: bce7e1da64 | B39: Mikael | E39: =SUMIFS(PedidodeCompra!F:F,PedidodeCompra!D:D,B:B) -> 0 | F39: =SUMIFS(PedidodeCompra!G:G,PedidodeCompra!D:D,B:B) -> 0 | G39: =E39-F39 -> 0
A40: bce7e1da49 | B40: Milho Conde | D40: Conde/BA | E40: =SUMIFS(PedidodeCompra!F:F,PedidodeCompra!D:D,B:B) -> 675634.35 | F40: =SUMIFS(PedidodeCompra!G:G,PedidodeCompra!D:D,B:B) -> 675634.35 | G40: =E40-F40 -> -1.1641532e-10
...

Sheet PedidodeCompra
A1: id | B1: Data | C1: NPedidoCompra | D1: Produtor | E1: CPF-CNPJ | F1: Valor Total | G1: Valor Pago | H1: Valor Pendente | I1: Safra | J1: Status | K1: Cidade | L1: MesAno | M1: PedCxMensal | N1: Gatilho | O1: Anotações
A2: b6a01109 | B2: 45674 | C2: 1701251261 | D2: Abrel | E2: Ronaldo Silva | F2: =SUMIFS(PedComCarrinho!E:E,PedComCarrinho!G:G,C:C) -> 56886.9 | G2: =SUMIFS(PagProdutor!F:F,PagProdutor!D:D,C:C)+(SUMIFS(PagComisao!F:F,PagComisao!K:K,C:C)) -> 56886.9 | H2: =F2-G2 -> 0 | I2: Safra Sergipe - 2025 | J2: Finalizado | K2: Não Informado/SE | L2: =TEXT(B2,"MM/YYYY") -> 01/2025 | M2: =IF(B2="","",CONCATENATE("CXG-",TEXT(B2,"MMYY"))) -> CXG-0125
A3: fcc79007 | B3: 45707 | C3: 1902252793 | D3: Alex Carira | E3: Newton Porto | F3: =SUMIFS(PedComCarrinho!E:E,PedComCarrinho!G:G,C:C) -> 355903.1 | G3: =SUMIFS(PagProdutor!F:F,PagProdutor!D:D,C:C)+(SUMIFS(PagComisao!F:F,PagComisao!K:K,C:C)) -> 355903.1 | H3: =F3-G3 -> 0 | I3: Safra Sergipe - 2025 | J3: Finalizado | K3: Carira/SE | L3: =TEXT(B3,"MM/YYYY") -> 02/2025 | M3: =IF(B3="","",CONCATENATE("CXG-",TEXT(B3,"MMYY"))) -> CXG-0225 | N3: 45755.371
A4: 1cce1744 | B4: 45729 | C4: 130325400 | D4: Anne Carira | E4: Ronaldo Silva | F4: =SUMIFS(PedComCarrinho!E:E,PedComCarrinho!G:G,C:C) -> 192693.6 | G4: =SUMIFS(PagProdutor!F:F,PagProdutor!D:D,C:C)+(SUMIFS(PagComisao!F:F,PagComisao!K:K,C:C)) -> 192693.6 | H4: =F4-G4 -> 0 | I4: Safra Sergipe - 2025 | J4: Finalizado | K4: Carira/SE | L4: =TEXT(B4,"MM/YYYY") -> 03/2025 | M4: =IF(B4="","",CONCATENATE("CXG-",TEXT(B4,"MMYY"))) -> CXG-0325 | N4: 45734.484
A5: 444dfa3a | B5: 45727 | C5: 1103253731 | D5: Bira do Queijo/Gararu | E5: Newton Porto | F5: =SUMIFS(PedComCarrinho!E:E,PedComCarrinho!G:G,C:C) -> 1034643.8 | G5: =SUMIFS(PagProdutor!F:F,PagProdutor!D:D,C:C)+(SUMIFS(PagComisao!F:F,PagComisao!K:K,C:C)) -> 1034643.8 | H5: =F5-G5 -> 0 | I5: Safra Sergipe - 2025 | J5: Finalizado | K5: Gararu/SE | L5: =TEXT(B5,"MM/YYYY") -> 03/2025 | M5: =IF(B5="","",CONCATENATE("CXG-",TEXT(B5,"MMYY"))) -> CXG-0325 | N5: 45826.811 | O5: 12.000 Sacos
A6: 82cd9bd4 | B6: 45794 | C6: 190525564 | D6: Bruna Piauí | E6: Ronaldo Silva | F6: =SUMIFS(PedComCarrinho!E:E,PedComCarrinho!G:G,C:C) -> 233793.78 | G6: =SUMIFS(PagProdutor!F:F,PagProdutor!D:D,C:C)+(SUMIFS(PagComisao!F:F,PagComisao!K:K,C:C)) -> 233793.78 | H6: =F6-G6 -> 0 | I6: Safra Maranhão - 2025 | J6: Finalizado | K6: Não Informado/PI | L6: =TEXT(B6,"MM/YYYY") -> 05/2025 | M6: =IF(B6="","",CONCATENATE("CXG-",TEXT(B6,"MMYY"))) -> CXG-0525
A7: a015525b | B7: 45691 | C7: 0302252193 | D7: Carlinhos | E7: Newton Porto | F7: =SUMIFS(PedComCarrinho!E:E,PedComCarrinho!G:G,C:C) -> 576400.01 | G7: =SUMIFS(PagProdutor!F:F,PagProdutor!D:D,C:C)+(SUMIFS(PagComisao!F:F,PagComisao!K:K,C:C)) -> 576400.01 | H7: =F7-G7 -> 0 | I7: Safra Sergipe - 2025 | J7: Finalizado | K7: Não Informado/SE | L7: =TEXT(B7,"MM/YYYY") -> 02/2025 | M7: =IF(B7="","",CONCATENATE("CXG-",TEXT(B7,"MMYY"))) -> CXG-0225 | N7: 45762.411
A8: fbf2f6b3 | B8: 45748 | C8: 0104254984 | D8: Cicero | E8: Ronaldo Silva | F8: =SUMIFS(PedComCarrinho!E:E,PedComCarrinho!G:G,C:C) -> 640390 | G8: =SUMIFS(PagProdutor!F:F,PagProdutor!D:D,C:C)+(SUMIFS(PagComisao!F:F,PagComisao!K:K,C:C)) -> 640390 | H8: =F8-G8 -> 0 | I8: Safra Sergipe - 2025 | J8: Finalizado | K8: Monte Alegre Sergipe/SE | L8: =TEXT(B8,"MM/YYYY") -> 04/2025 | M8: =IF(B8="","",CONCATENATE("CXG-",TEXT(B8,"MMYY"))) -> CXG-0425 | N8: 45764.57
A9: 2eb078ac | B9: 45673 | C9: 160125555 | D9: Clair Feira Nova | E9: Ronaldo Silva | F9: =SUMIFS(PedComCarrinho!E:E,PedComCarrinho!G:G,C:C) -> 12478.5 | G9: =SUMIFS(PagProdutor!F:F,PagProdutor!D:D,C:C)+(SUMIFS(PagComisao!F:F,PagComisao!K:K,C:C)) -> 12478.5 | H9: =F9-G9 -> 0 | I9: Safra Sergipe - 2025 | J9: Finalizado | K9: Feira Nova/SE | L9: =TEXT(B9,"MM/YYYY") -> 01/2025 | M9: =IF(B9="","",CONCATENATE("CXG-",TEXT(B9,"MMYY"))) -> CXG-0125
A10: fc815116 | B10: 45699 | C10: 1102252310 | D10: Comprovante de 4.895,00 | E10: Ronaldo Silva | F10: =SUMIFS(PedComCarrinho!E:E,PedComCarrinho!G:G,C:C) -> 0 | G10: =SUMIFS(PagProdutor!F:F,PagProdutor!D:D,C:C)+(SUMIFS(PagComisao!F:F,PagComisao!K:K,C:C)) -> 0 | H10: =F10-G10 -> 0 | I10: Safra Sergipe - 2025 | J10: Finalizado | K10: Não Informado/SE | L10: =TEXT(B10,"MM/YYYY") -> 02/2025 | M10: =IF(B10="","",CONCATENATE("CXG-",TEXT(B10,"MMYY"))) -> CXG-0225
A11: 92fc0d7b | B11: 45675 | C11: 200125137 | D11: Edenilson Balsas | E11: Ronaldo Silva | F11: =SUMIFS(PedComCarrinho!E:E,PedComCarrinho!G:G,C:C) -> 230806.63 | G11: =SUMIFS(PagProdutor!F:F,PagProdutor!D:D,C:C)+(SUMIFS(PagComisao!F:F,PagComisao!K:K,C:C)) -> 230806.63 | H11: =F11-G11 -> 0 | I11: Safra Maranhão - 2025 | J11: Finalizado | K11: Balsas/MA | L11: =TEXT(B11,"MM/YYYY") -> 01/2025 | M11: =IF(B11="","",CONCATENATE("CXG-",TEXT(B11,"MMYY"))) -> CXG-0125
A12: 55529feb | B12: 45699 | C12: 1102252412 | D12: Elizabete | E12: Ronaldo Silva | F12: =SUMIFS(PedComCarrinho!E:E,PedComCarrinho!G:G,C:C) -> 193875.89 | G12: =SUMIFS(PagProdutor!F:F,PagProdutor!D:D,C:C)+(SUMIFS(PagComisao!F:F,PagComisao!K:K,C:C)) -> 193875.89 | H12: =F12-G12 -> 0 | I12: Safra Sergipe - 2025 | J12: Finalizado | K12: Não Informado/SE | L12: =TEXT(B12,"MM/YYYY") -> 02/2025 | M12: =IF(B12="","",CONCATENATE("CXG-",TEXT(B12,"MMYY"))) -> CXG-0225
A13: 0b5370b8 | B13: 45721 | C13: 0503253270 | D13: Elizeu | E13: Newton Porto | F13: =SUMIFS(PedComCarrinho!E:E,PedComCarrinho!G:G,C:C) -> 1507330.4 | G13: =SUMIFS(PagProdutor!F:F,PagProdutor!D:D,C:C)+(SUMIFS(PagComisao!F:F,PagComisao!K:K,C:C)) -> 1507330.4 | H13: =F13-G13 -> -2.3283064e-10 | I13: Safra Sergipe - 2025 | J13: Finalizado | K13: Não Informado/SE | L13: =TEXT(B13,"MM/YYYY") -> 03/2025 | M13: =IF(B13="","",CONCATENATE("CXG-",TEXT(B13,"MMYY"))) -> CXG-0325 | N13: 45727.623
A14: 48c3969e | B14: 45666 | C14: 150125254 | D14: Eudas | E14: Ronaldo Silva | F14: =SUMIFS(PedComCarrinho!E:E,PedComCarrinho!G:G,C:C) -> 305564.32 | G14: =SUMIFS(PagProdutor!F:F,PagProdutor!D:D,C:C)+(SUMIFS(PagComisao!F:F,PagComisao!K:K,C:C)) -> 305564.32 | H14: =F14-G14 -> 0 | I14: Safra Sergipe - 2025 | J14: Finalizado | K14: Siriri/SE | L14: =TEXT(B14,"MM/YYYY") -> 01/2025 | M14: =IF(B14="","",CONCATENATE("CXG-",TEXT(B14,"MMYY"))) -> CXG-0125 | N14: 45673.676
A15: 7c523a62 | B15: 45666 | C15: 160125346 | D15: Francisco Benjamin | E15: Ronaldo Silva | F15: =SUMIFS(PedComCarrinho!E:E,PedComCarrinho!G:G,C:C) -> 82041 | G15: =SUMIFS(PagProdutor!F:F,PagProdutor!D:D,C:C)+(SUMIFS(PagComisao!F:F,PagComisao!K:K,C:C)) -> 82041 | H15: =F15-G15 -> 0 | I15: Safra Sergipe - 2025 | J15: Finalizado | K15: Cristinapolis/SE | L15: =TEXT(B15,"MM/YYYY") -> 01/2025 | M15: =IF(B15="","",CONCATENATE("CXG-",TEXT(B15,"MMYY"))) -> CXG-0125 | N15: 45961.543
A16: 2f2fb276 | B16: 45673 | C16: 160125786 | D16: Gabriel Balsas - Gilmar | E16: Ronaldo Silva | F16: =SUMIFS(PedComCarrinho!E:E,PedComCarrinho!G:G,C:C) -> 133336.38 | G16: =SUMIFS(PagProdutor!F:F,PagProdutor!D:D,C:C)+(SUMIFS(PagComisao!F:F,PagComisao!K:K,C:C)) -> 133336.38 | H16: =F16-G16 -> 0 | I16: Safra Maranhão - 2025 | J16: Finalizado | K16: Balsas/MA | L16: =TEXT(B16,"MM/YYYY") -> 01/2025 | M16: =IF(B16="","",CONCATENATE("CXG-",TEXT(B16,"MMYY"))) -> CXG-0125 | N16: 45674.656
A17: 5b5451b5 | B17: 45674 | C17: 1701251075 | D17: Gabriel Balsas - Gilmar | E17: Newton Porto | F17: =SUMIFS(PedComCarrinho!E:E,PedComCarrinho!G:G,C:C) -> 629607.08 | G17: =SUMIFS(PagProdutor!F:F,PagProdutor!D:D,C:C)+(SUMIFS(PagComisao!F:F,PagComisao!K:K,C:C)) -> 629607.08 | H17: =F17-G17 -> 0 | I17: Safra Maranhão - 2025 | J17: Finalizado | K17: Balsas/MA | L17: =TEXT(B17,"MM/YYYY") -> 01/2025 | M17: =IF(B17="","",CONCATENATE("CXG-",TEXT(B17,"MMYY"))) -> CXG-0125 | N17: 45675.308 | O17: 15.000 Sc
A18: a7a959b1 | B18: 45726 | C18: 1003253515 | D18: Gabriel Balsas - Gilmar | E18: Newton Porto | F18: =SUMIFS(PedComCarrinho!E:E,PedComCarrinho!G:G,C:C) -> 694392.08 | G18: =SUMIFS(PagProdutor!F:F,PagProdutor!D:D,C:C)+(SUMIFS(PagComisao!F:F,PagComisao!K:K,C:C)) -> 694392.08 | H18: =F18-G18 -> 1.1641532e-10 | I18: Safra Maranhão - 2025 | J18: Finalizado | K18: Balsas/MA | L18: =TEXT(B18,"MM/YYYY") -> 03/2025 | M18: =IF(B18="","",CONCATENATE("CXG-",TEXT(B18,"MMYY"))) -> CXG-0325 | N18: 45733.796 | O18: 5.000 Sacos
A19: 43fe61fc | B19: 45693 | C19: 0502252287 | D19: Gabriel Balsas - Pedro | E19: Newton Porto | F19: =SUMIFS(PedComCarrinho!E:E,PedComCarrinho!G:G,C:C) -> 151510.51 | G19: =SUMIFS(PagProdutor!F:F,PagProdutor!D:D,C:C)+(SUMIFS(PagComisao!F:F,PagComisao!K:K,C:C)) -> 151510.51 | H19: =F19-G19 -> 0 | I19: Safra Maranhão - 2025 | J19: Finalizado | K19: Balsas/MA | L19: =TEXT(B19,"MM/YYYY") -> 02/2025 | M19: =IF(B19="","",CONCATENATE("CXG-",TEXT(B19,"MMYY"))) -> CXG-0225
A20: 7c5f3047 | B20: 45674 | C20: 170125830 | D20: Gabriel Balsas/Irineu | E20: Newton Porto | F20: =SUMIFS(PedComCarrinho!E:E,PedComCarrinho!G:G,C:C) -> 310557.12 | G20: =SUMIFS(PagProdutor!F:F,PagProdutor!D:D,C:C)+(SUMIFS(PagComisao!F:F,PagComisao!K:K,C:C)) -> 310557.12 | H20: =F20-G20 -> 0 | I20: Safra Maranhão - 2025 | J20: Finalizado | K20: Balsas/MA | L20: =TEXT(B20,"MM/YYYY") -> 01/2025 | M20: =IF(B20="","",CONCATENATE("CXG-",TEXT(B20,"MMYY"))) -> CXG-0125 | N20: 46034.432
A21: de87a851 | B21: 45677 | C21: 2001251462 | D21: Gabriel Balsas/Irineu | E21: Newton Porto | F21: =SUMIFS(PedComCarrinho!E:E,PedComCarrinho!G:G,C:C) -> 818752.95 | G21: =SUMIFS(PagProdutor!F:F,PagProdutor!D:D,C:C)+(SUMIFS(PagComisao!F:F,PagComisao!K:K,C:C)) -> 818752.95 | H21: =F21-G21 -> 0 | I21: Safra Maranhão - 2025 | J21: Finalizado | K21: Balsas/MA | L21: =TEXT(B21,"MM/YYYY") -> 01/2025 | M21: =IF(B21="","",CONCATENATE("CXG-",TEXT(B21,"MMYY"))) -> CXG-0125 | N21: 46034.432 | O21: 8.000 Sc
A22: 5ecd11a7 | B22: 45726 | C22: 1003253656 | D22: Gabriel Balsas/Irineu | E22: Newton Porto | F22: =SUMIFS(PedComCarrinho!E:E,PedComCarrinho!G:G,C:C) -> 448643.13 | G22: =SUMIFS(PagProdutor!F:F,PagProdutor!D:D,C:C)+(SUMIFS(PagComisao!F:F,PagComisao!K:K,C:C)) -> 448643.13 | H22: =F22-G22 -> 0 | I22: Safra Maranhão - 2025 | J22: Finalizado | K22: Balsas/MA | L22: =TEXT(B22,"MM/YYYY") -> 03/2025 | M22: =IF(B22="","",CONCATENATE("CXG-",TEXT(B22,"MMYY"))) -> CXG-0325 | N22: 46034.432
A23: bac4eaba | B23: 45751 | C23: 0404255072 | D23: Gabriel Balsas/Irineu | E23: Newton Porto | F23: =SUMIFS(PedComCarrinho!E:E,PedComCarrinho!G:G,C:C) -> 0 | G23: =SUMIFS(PagProdutor!F:F,PagProdutor!D:D,C:C)+(SUMIFS(PagComisao!F:F,PagComisao!K:K,C:C)) -> 126450 | H23: =F23-G23 -> -126450 | I23: Safra Maranhão - 2025 | J23: Finalizado | K23: Balsas/MA | L23: =TEXT(B23,"MM/YYYY") -> 04/2025 | M23: =IF(B23="","",CONCATENATE("CXG-",TEXT(B23,"MMYY"))) -> CXG-0425 | N23: 46034.432
A24: fc66466c | B24: 45799 | C24: 2205255791 | D24: Gabriel Balsas/Marcos | E24: Newton Porto | F24: =SUMIFS(PedComCarrinho!E:E,PedComCarrinho!G:G,C:C) -> 451381.76 | G24: =SUMIFS(PagProdutor!F:F,PagProdutor!D:D,C:C)+(SUMIFS(PagComisao!F:F,PagComisao!K:K,C:C)) -> 451381.76 | H24: =F24-G24 -> 0 | I24: Safra Maranhão - 2025 | J24: Finalizado | K24: Balsas/MA | L24: =TEXT(B24,"MM/YYYY") -> 05/2025 | M24: =IF(B24="","",CONCATENATE("CXG-",TEXT(B24,"MMYY"))) -> CXG-0525 | N24: 45805.449
A25: a57010c7 | B25: 45702 | C25: 140225260 | D25: Gabriel Melo - Itabi | E25: Ronaldo Silva | F25: =SUMIFS(PedComCarrinho!E:E,PedComCarrinho!G:G,C:C) -> 302174.46 | G25: =SUMIFS(PagProdutor!F:F,PagProdutor!D:D,C:C)+(SUMIFS(PagComisao!F:F,PagComisao!K:K,C:C)) -> 302174.46 | H25: =F25-G25 -> 0 | I25: Safra Sergipe - 2025 | J25: Finalizado | K25: Itabi/SE | L25: =TEXT(B25,"MM/YYYY") -> 02/2025 | M25: =IF(B25="","",CONCATENATE("CXG-",TEXT(B25,"MMYY"))) -> CXG-0225
A26: dbf9c9ce | B26: 45724 | C26: 0803253478 | D26: George | E26: Newton Porto | F26: =SUMIFS(PedComCarrinho!E:E,PedComCarrinho!G:G,C:C) -> 134313.5 | G26: =SUMIFS(PagProdutor!F:F,PagProdutor!D:D,C:C)+(SUMIFS(PagComisao!F:F,PagComisao!K:K,C:C)) -> 134313.5 | H26: =F26-G26 -> 0 | I26: Safra Sergipe - 2025 | J26: Finalizado | K26: Não Informado/SE | L26: =TEXT(B26,"MM/YYYY") -> 03/2025 | M26: =IF(B26="","",CONCATENATE("CXG-",TEXT(B26,"MMYY"))) -> CXG-0325
A27: eae571f7 | B27: 45682 | C27: 2501251862 | D27: George Tocantins | E27: Newton Porto | F27: =SUMIFS(PedComCarrinho!E:E,PedComCarrinho!G:G,C:C) -> 99054.65 | G27: =SUMIFS(PagProdutor!F:F,PagProdutor!D:D,C:C)+(SUMIFS(PagComisao!F:F,PagComisao!K:K,C:C)) -> 99054.65 | H27: =F27-G27 -> 0 | I27: Safra Tocantins - 2025 | J27: Finalizado | K27: Não informado/TO | L27: =TEXT(B27,"MM/YYYY") -> 01/2025 | M27: =IF(B27="","",CONCATENATE("CXG-",TEXT(B27,"MMYY"))) -> CXG-0125
A28: 78fd0117 | B28: 45701 | C28: 1302252597 | D28: Guilherme Balsas | E28: Newton Porto | F28: =SUMIFS(PedComCarrinho!E:E,PedComCarrinho!G:G,C:C) -> 478599.91 | G28: =SUMIFS(PagProdutor!F:F,PagProdutor!D:D,C:C)+(SUMIFS(PagComisao!F:F,PagComisao!K:K,C:C)) -> 478599.91 | H28: =F28-G28 -> -1.1641532e-10 | I28: Safra Maranhão - 2025 | J28: Finalizado | K28: Balsas/MA | L28: =TEXT(B28,"MM/YYYY") -> 02/2025 | M28: =IF(B28="","",CONCATENATE("CXG-",TEXT(B28,"MMYY"))) -> CXG-0225 | N28: 45840.713
A29: b95fcfbc | B29: 45717 | C29: 0103253196 | D29: Guilherme Balsas | E29: Newton Porto | F29: =SUMIFS(PedComCarrinho!E:E,PedComCarrinho!G:G,C:C) -> 154684.23 | G29: =SUMIFS(PagProdutor!F:F,PagProdutor!D:D,C:C)+(SUMIFS(PagComisao!F:F,PagComisao!K:K,C:C)) -> 154684.23 | H29: =F29-G29 -> 0 | I29: Safra Maranhão - 2025 | J29: Finalizado | K29: Balsas/MA | L29: =TEXT(B29,"MM/YYYY") -> 03/2025 | M29: =IF(B29="","",CONCATENATE("CXG-",TEXT(B29,"MMYY"))) -> CXG-0325 | N29: 45840.713
A30: 9b2f2c55 | B30: 45745 | C30: 2903254715 | D30: Guilherme Balsas | E30: Newton Porto | F30: =SUMIFS(PedComCarrinho!E:E,PedComCarrinho!G:G,C:C) -> 158917.61 | G30: =SUMIFS(PagProdutor!F:F,PagProdutor!D:D,C:C)+(SUMIFS(PagComisao!F:F,PagComisao!K:K,C:C)) -> 158917.61 | H30: =F30-G30 -> 0 | I30: Safra Maranhão - 2025 | J30: Finalizado | K30: Balsas/MA | L30: =TEXT(B30,"MM/YYYY") -> 03/2025 | M30: =IF(B30="","",CONCATENATE("CXG-",TEXT(B30,"MMYY"))) -> CXG-0325 | N30: 45840.713
A31: 6287be31 | B31: 45789 | C31: 1205255544 | D31: Guilherme Balsas | E31: Newton Porto | F31: =SUMIFS(PedComCarrinho!E:E,PedComCarrinho!G:G,C:C) -> 1120061.9 | G31: =SUMIFS(PagProdutor!F:F,PagProdutor!D:D,C:C)+(SUMIFS(PagComisao!F:F,PagComisao!K:K,C:C)) -> 1120061.9 | H31: =F31-G31 -> -4.6566129e-10 | I31: Safra Maranhão - 2025 | J31: Finalizado | K31: Balsas/MA | L31: =TEXT(B31,"MM/YYYY") -> 05/2025 | M31: =IF(B31="","",CONCATENATE("CXG-",TEXT(B31,"MMYY"))) -> CXG-0525 | N31: 45840.713
A32: 28831be7 | B32: 45782 | C32: 0505255299 | D32: Guilherme Piaui | E32: Newton Porto | F32: =SUMIFS(PedComCarrinho!E:E,PedComCarrinho!G:G,C:C) -> 656990.37 | G32: =SUMIFS(PagProdutor!F:F,PagProdutor!D:D,C:C)+(SUMIFS(PagComisao!F:F,PagComisao!K:K,C:C)) -> 656990.37 | H32: =F32-G32 -> -1.1641532e-10 | I32: Safra Maranhão - 2025 | J32: Finalizado | K32: São Francisco Do Piaui/PI | L32: =TEXT(B32,"MM/YYYY") -> 05/2025 | M32: =IF(B32="","",CONCATENATE("CXG-",TEXT(B32,"MMYY"))) -> CXG-0525 | N32: 45840.713
A33: 1a889c5c | B33: 45727 | C33: 1103253994 | D33: Jair | E33: Newton Porto | F33: =SUMIFS(PedComCarrinho!E:E,PedComCarrinho!G:G,C:C) -> 1209652 | G33: =SUMIFS(PagProdutor!F:F,PagProdutor!D:D,C:C)+(SUMIFS(PagComisao!F:F,PagComisao!K:K,C:C)) -> 1209652 | H33: =F33-G33 -> 0 | I33: Safra Sergipe - 2025 | J33: Finalizado | K33: Não Informado/SE | L33: =TEXT(B33,"MM/YYYY") -> 03/2025 | M33: =IF(B33="","",CONCATENATE("CXG-",TEXT(B33,"MMYY"))) -> CXG-0325 | N33: 45741.399 | O33: 15.000 Sacos
A34: f5cced4e | B34: 45674 | C34: 170125967 | D34: José Nunes | E34: Ronaldo Silva | F34: =SUMIFS(PedComCarrinho!E:E,PedComCarrinho!G:G,C:C) -> 376398.23 | G34: =SUMIFS(PagProdutor!F:F,PagProdutor!D:D,C:C)+(SUMIFS(PagComisao!F:F,PagComisao!K:K,C:C)) -> 376398.23 | H34: =F34-G34 -> 0 | I34: Safra Sergipe - 2025 | J34: Finalizado | K34: Aracaju/SE | L34: =TEXT(B34,"MM/YYYY") -> 01/2025 | M34: =IF(B34="","",CONCATENATE("CXG-",TEXT(B34,"MMYY"))) -> CXG-0125
A35: 24f54b44 | B35: 45784 | C35: 0705255335 | D35: Jr Grao | E35: Newton Porto | F35: =SUMIFS(PedComCarrinho!E:E,PedComCarrinho!G:G,C:C) -> 958633.62 | G35: =SUMIFS(PagProdutor!F:F,PagProdutor!D:D,C:C)+(SUMIFS(PagComisao!F:F,PagComisao!K:K,C:C)) -> 958633.62 | H35: =F35-G35 -> 0 | I35: Safra Maranhão - 2025 | J35: Finalizado | K35: Não Informado/MA | L35: =TEXT(B35,"MM/YYYY") -> 05/2025 | M35: =IF(B35="","",CONCATENATE("CXG-",TEXT(B35,"MMYY"))) -> CXG-0525 | N35: 45796.456
A36: 9b9b53e8 | B36: 45671 | C36: 160125470 | D36: Kelly Itabaianinha | E36: Newton Porto | F36: =SUMIFS(PedComCarrinho!E:E,PedComCarrinho!G:G,C:C) -> 917307.45 | G36: =SUMIFS(PagProdutor!F:F,PagProdutor!D:D,C:C)+(SUMIFS(PagComisao!F:F,PagComisao!K:K,C:C)) -> 917307.45 | H36: =F36-G36 -> 1.1641532e-10 | I36: Safra Sergipe - 2025 | J36: Finalizado | K36: Itabaiana/SE | L36: =TEXT(B36,"MM/YYYY") -> 01/2025 | M36: =IF(B36="","",CONCATENATE("CXG-",TEXT(B36,"MMYY"))) -> CXG-0125 | N36: 45684.359
A37: 50b52b50 | B37: 45680 | C37: 2301251745 | D37: Lucas LEM | E37: Newton Porto | F37: =SUMIFS(PedComCarrinho!E:E,PedComCarrinho!G:G,C:C) -> 47291.04 | G37: =SUMIFS(PagProdutor!F:F,PagProdutor!D:D,C:C)+(SUMIFS(PagComisao!F:F,PagComisao!K:K,C:C)) -> 47291.04 | H37: =F37-G37 -> 0 | I37: Safra Bahia - 2025 | J37: Finalizado | K37: Luis Eduardo Magalhães/BA | L37: =TEXT(B37,"MM/YYYY") -> 01/2025 | M37: =IF(B37="","",CONCATENATE("CXG-",TEXT(B37,"MMYY"))) -> CXG-0125
A38: df13086e | B38: 45674 | C38: 1701251131 | D38: Lucas Sobral | E38: Ronaldo Silva | F38: =SUMIFS(PedComCarrinho!E:E,PedComCarrinho!G:G,C:C) -> 962320.53 | G38: =SUMIFS(PagProdutor!F:F,PagProdutor!D:D,C:C)+(SUMIFS(PagComisao!F:F,PagComisao!K:K,C:C)) -> 962320.53 | H38: =F38-G38 -> 0 | I38: Safra Sergipe - 2025 | J38: Finalizado | K38: Não Informado/SE | L38: =TEXT(B38,"MM/YYYY") -> 01/2025 | M38: =IF(B38="","",CONCATENATE("CXG-",TEXT(B38,"MMYY"))) -> CXG-0125 | N38: 45870.582
A39: 1661f60f | B39: 45707 | C39: 1902252883 | D39: Luiz Médio | E39: Newton Porto | F39: =SUMIFS(PedComCarrinho!E:E,PedComCarrinho!G:G,C:C) -> 74128.77 | G39: =SUMIFS(PagProdutor!F:F,PagProdutor!D:D,C:C)+(SUMIFS(PagComisao!F:F,PagComisao!K:K,C:C)) -> 74128.77 | H39: =F39-G39 -> 0 | I39: Safra Sergipe - 2025 | J39: Finalizado | K39: Não Informado/SE | L39: =TEXT(B39,"MM/YYYY") -> 02/2025 | M39: =IF(B39="","",CONCATENATE("CXG-",TEXT(B39,"MMYY"))) -> CXG-0225
A40: 26439106 | B40: 45738 | C40: 2303254374 | D40: Marcelo Cumbe | E40: Ronaldo Silva | F40: =SUMIFS(PedComCarrinho!E:E,PedComCarrinho!G:G,C:C) -> 187120 | G40: =SUMIFS(PagProdutor!F:F,PagProdutor!D:D,C:C)+(SUMIFS(PagComisao!F:F,PagComisao!K:K,C:C)) -> 187120 | H40: =F40-G40 -> 0 | I40: Safra Sergipe - 2025 | J40: Finalizado | K40: Cumbe/SE | L40: =TEXT(B40,"MM/YYYY") -> 03/2025 | M40: =IF(B40="","",CONCATENATE("CXG-",TEXT(B40,"MMYY"))) -> CXG-0325 | N40: 45741.4
...

Sheet PedComCarrinho
A1: ID | B1: Produto | C1: Quantidade KG | D1: Quantidade SC | E1: Valor Total | F1: Valor Unit Medio | G1: PedidodeCompra
A2: 136758a2 | B2: Milho em Grãos | C2: =SUMIFS(CarrinhoFretes!D:D,CarrinhoFretes!U:U,G:G) -> 260980 | D2: =C2/60 -> 4349.6667 | E2: =SUMIFS(CarrinhoFretes!G:G,CarrinhoFretes!U:U,G:G) -> 305564.32 | F2: =IF(D2=0, 0, E2/D2) -> 70.250054 | G2: 150125254
A3: 5cfa751e | B3: Milho em Grãos | C3: =SUMIFS(CarrinhoFretes!D:D,CarrinhoFretes!U:U,G:G) -> 71340 | D3: =C3/60 -> 1189 | E3: =SUMIFS(CarrinhoFretes!G:G,CarrinhoFretes!U:U,G:G) -> 82041 | F3: =IF(D3=0, 0, E3/D3) -> 69 | G3: 160125346
A4: d2e35695 | B4: Milho em Grãos | C4: =SUMIFS(CarrinhoFretes!D:D,CarrinhoFretes!U:U,G:G) -> 772950 | D4: =C4/60 -> 12882.5 | E4: =SUMIFS(CarrinhoFretes!G:G,CarrinhoFretes!U:U,G:G) -> 917307.45 | F4: =IF(D4=0, 0, E4/D4) -> 71.205702 | G4: 160125470
A5: ba126ea2 | B5: Milho em Grãos | C5: =SUMIFS(CarrinhoFretes!D:D,CarrinhoFretes!U:U,G:G) -> 10620 | D5: =C5/60 -> 177 | E5: =SUMIFS(CarrinhoFretes!G:G,CarrinhoFretes!U:U,G:G) -> 12478.5 | F5: =IF(D5=0, 0, E5/D5) -> 70.5 | G5: 160125555
A6: 15fa2e1a | B6: Milho em Grãos | C6: =SUMIFS(CarrinhoFretes!D:D,CarrinhoFretes!U:U,G:G) -> 250920 | D6: =C6/60 -> 4182 | E6: =SUMIFS(CarrinhoFretes!G:G,CarrinhoFretes!U:U,G:G) -> 292740.7 | F6: =IF(D6=0, 0, E6/D6) -> 70.000167 | G6: 160125657
A7: 6ee635db | B7: Milho em Grãos | C7: =SUMIFS(CarrinhoFretes!D:D,CarrinhoFretes!U:U,G:G) -> 122140 | D7: =C7/60 -> 2035.6667 | E7: =SUMIFS(CarrinhoFretes!G:G,CarrinhoFretes!U:U,G:G) -> 133336.38 | F7: =IF(D7=0, 0, E7/D7) -> 65.500105 | G7: 160125786
A8: f48effec | B8: Milho em Grãos | C8: =SUMIFS(CarrinhoFretes!D:D,CarrinhoFretes!U:U,G:G) -> 284480 | D8: =C8/60 -> 4741.3333 | E8: =SUMIFS(CarrinhoFretes!G:G,CarrinhoFretes!U:U,G:G) -> 310557.12 | F8: =IF(D8=0, 0, E8/D8) -> 65.499955 | G8: 170125830
A9: 4b1be3cf | B9: Milho em Grãos | C9: =SUMIFS(CarrinhoFretes!D:D,CarrinhoFretes!U:U,G:G) -> 325300 | D9: =C9/60 -> 5421.6667 | E9: =SUMIFS(CarrinhoFretes!G:G,CarrinhoFretes!U:U,G:G) -> 376398.23 | F9: =IF(D9=0, 0, E9/D9) -> 69.42482 | G9: 170125967
A10: 5131bb60 | B10: Milho em Grãos | C10: =SUMIFS(CarrinhoFretes!D:D,CarrinhoFretes!U:U,G:G) -> 578080 | D10: =C10/60 -> 9634.6667 | E10: =SUMIFS(CarrinhoFretes!G:G,CarrinhoFretes!U:U,G:G) -> 629607.08 | F10: =IF(D10=0, 0, E10/D10) -> 65.348092 | G10: 1701251075
A11: 2e326eed | B11: Milho em Grãos | C11: =SUMIFS(CarrinhoFretes!D:D,CarrinhoFretes!U:U,G:G) -> 723320 | D11: =C11/60 -> 12055.333 | E11: =SUMIFS(CarrinhoFretes!G:G,CarrinhoFretes!U:U,G:G) -> 962320.53 | F11: =IF(D11=0, 0, E11/D11) -> 79.825294 | G11: 1701251131
A12: c537334c | B12: Milho em Grãos | C12: =SUMIFS(CarrinhoFretes!D:D,CarrinhoFretes!U:U,G:G) -> 48760 | D12: =C12/60 -> 812.66667 | E12: =SUMIFS(CarrinhoFretes!G:G,CarrinhoFretes!U:U,G:G) -> 56886.9 | F12: =IF(D12=0, 0, E12/D12) -> 70.000287 | G12: 1701251261
A13: e114a584 | B13: Milho em Grãos | C13: =SUMIFS(CarrinhoFretes!D:D,CarrinhoFretes!U:U,G:G) -> 213610 | D13: =C13/60 -> 3560.1667 | E13: =SUMIFS(CarrinhoFretes!G:G,CarrinhoFretes!U:U,G:G) -> 230806.63 | F13: =IF(D13=0, 0, E13/D13) -> 64.830288 | G13: 200125137
... A231: aeeb002d | B231: Milho em Grãos | C231: =SUMIFS(CarrinhoFretes!D:D,CarrinhoFretes!U:U,G:G) -> 1011560 | D231: =C231/60 -> 16859.333 | E231: =SUMIFS(CarrinhoFretes!G:G,CarrinhoFretes!U:U,G:G) -> 854069.82 | F231: =IF(D231=0, 0, E231/D231) -> 50.658576 | G231: 26052623088

Sheet PagProdutor
A1: ID | B1: Data | C1: Produtor | D1: PedidodeCompra | E1: Conta | F1: Valor | G1: Anexo | H1: Foto | I1: Anotações | J1: MesAno | K1: PedCxMensal
A2: 468cff49 | B2: 45671 | C2: Eudas | D2: 150125254 | E2: N.Nordeste - B.Brasil | F2: 152238.45 | J2: =TEXT(B2,"MM/YYYY") -> 01/2025 | K2: =IF(B2="","",CONCATENATE("CXG-",TEXT(B2,"MMYY"))) -> CXG-0125
A3: 3449b0de | B3: 45671 | C3: Eudas | D3: 150125254 | E3: N.Nordeste - B.Brasil | F3: 152238.45 | J3: =TEXT(B3,"MM/YYYY") -> 01/2025 | K3: =IF(B3="","",CONCATENATE("CXG-",TEXT(B3,"MMYY"))) -> CXG-0125
A4: 9da228b8 | B4: 45671 | C4: Kelly Itabaianinha | D4: 160125470 | E4: N.Nordeste - B.Brasil | F4: 62370 | J4: =TEXT(B4,"MM/YYYY") -> 01/2025 | K4: =IF(B4="","",CONCATENATE("CXG-",TEXT(B4,"MMYY"))) -> CXG-0125
A5: b13aad7d | B5: 45671 | C5: Kelly Itabaianinha | D5: 160125470 | E5: N.Nordeste - B.Brasil | F5: 59780 | J5: =TEXT(B5,"MM/YYYY") -> 01/2025 | K5: =IF(B5="","",CONCATENATE("CXG-",TEXT(B5,"MMYY"))) -> CXG-0125
A6: a1fb25b6 | B6: 45671 | C6: Gabriel Balsas/Irineu | D6: 170125830 | E6: N.Nordeste - B.Brasil | F6: 7881.9 | J6: =TEXT(B6,"MM/YYYY") -> 01/2025 | K6: =IF(B6="","",CONCATENATE("CXG-",TEXT(B6,"MMYY"))) -> CXG-0125
A7: 4f337c36 | B7: 45671 | C7: Gabriel Balsas/Irineu | D7: 170125830 | E7: N.Nordeste - B.Brasil | F7: 300000 | J7: =TEXT(B7,"MM/YYYY") -> 01/2025 | K7: =IF(B7="","",CONCATENATE("CXG-",TEXT(B7,"MMYY"))) -> CXG-0125
A8: 5c5991dc | B8: 45672 | C8: Clair Feira Nova | D8: 160125555 | E8: N.Nordeste - B.Brasil | F8: 12300 | J8: =TEXT(B8,"MM/YYYY") -> 01/2025 | K8: =IF(B8="","",CONCATENATE("CXG-",TEXT(B8,"MMYY"))) -> CXG-0125
A9: 3ba26342 | B9: 45672 | C9: Clair Feira Nova | D9: 160125555 | E9: Descontos | F9: 100 | I9: Balança | J9: =TEXT(B9,"MM/YYYY") -> 01/2025 | K9: =IF(B9="","",CONCATENATE("CXG-",TEXT(B9,"MMYY"))) -> CXG-0125
A10: c44a15f9 | B10: 45672 | C10: Kelly Itabaianinha | D10: 160125470 | E10: N.Nordeste - B.Brasil | F10: 83883.33 | J10: =TEXT(B10,"MM/YYYY") -> 01/2025 | K10: =IF(B10="","",CONCATENATE("CXG-",TEXT(B10,"MMYY"))) -> CXG-0125
A11: 447d0a02 | B11: 45672 | C11: Kelly Itabaianinha | D11: 160125470 | E11: N.Nordeste - B.Brasil | F11: 80990 | J11: =TEXT(B11,"MM/YYYY") -> 01/2025 | K11: =IF(B11="","",CONCATENATE("CXG-",TEXT(B11,"MMYY"))) -> CXG-0125
A12: da1c5653 | B12: 45673 | C12: Gabriel Balsas - Gilmar | D12: 160125786 | E12: S.Grão - Sicredi | F12: 132340 | I12: Pagou 21,45 a mais | J12: =TEXT(B12,"MM/YYYY") -> 01/2025 | K12: =IF(B12="","",CONCATENATE("CXG-",TEXT(B12,"MMYY"))) -> CXG-0125
A13: 60c722b3 | B13: 45673 | C13: Gabriel Balsas - Gilmar | D13: 160125786 | E13: Pgmt Indevido | F13: -21.45 | J13: =TEXT(B13,"MM/YYYY") -> 01/2025 | K13: =IF(B13="","",CONCATENATE("CXG-",TEXT(B13,"MMYY"))) -> CXG-0125
A14: b8a482b0 | B14: 45673 | C14: José Nunes | D14: 170125967 | E14: N.Nordeste - B.Brasil | F14: 160000 | I14: Adiantamento | J14: =TEXT(B14,"MM/YYYY") -> 01/2025 | K14: =IF(B14="","",CONCATENATE("CXG-",TEXT(B14,"MMYY"))) -> CXG-0125
A15: c8c449b5 | B15: 45673 | C15: Gabriel Balsas/Irineu | D15: 170125830 | E15: N.Nordeste - B.Brasil | F15: 304.72 | J15: =TEXT(B15,"MM/YYYY") -> 01/2025 | K15: =IF(B15="","",CONCATENATE("CXG-",TEXT(B15,"MMYY"))) -> CXG-0125
A16: 15abe9b2 | B16: 45674 | C16: Kelly Itabaianinha | D16: 160125470 | E16: S.Grão - Sicredi | F16: 74526.67 | J16: =TEXT(B16,"MM/YYYY") -> 01/2025 | K16: =IF(B16="","",CONCATENATE("CXG-",TEXT(B16,"MMYY"))) -> CXG-0125
A17: b4cf1ade | B17: 45675 | C17: Kelly Itabaianinha | D17: 160125470 | E17: S.Grão - Sicredi | F17: 150000 | J17: =TEXT(B17,"MM/YYYY") -> 01/2025 | K17: =IF(B17="","",CONCATENATE("CXG-",TEXT(B17,"MMYY"))) -> CXG-0125
A18: 9378dcb2 | B18: 45675 | C18: Kelly Itabaianinha | D18: 160125470 | E18: S.Grão - Sicredi | F18: 71713 | J18: =TEXT(B18,"MM/YYYY") -> 01/2025 | K18: =IF(B18="","",CONCATENATE("CXG-",TEXT(B18,"MMYY"))) -> CXG-0125
A19: d7b6148d | B19: 45675 | C19: Edenilson Balsas | D19: 200125137 | E19: S.Grão - Sicredi | F19: 73760 | J19: =TEXT(B19,"MM/YYYY") -> 01/2025 | K19: =IF(B19="","",CONCATENATE("CXG-",TEXT(B19,"MMYY"))) -> CXG-0125
A20: 2f4ad352 | B20: 45677 | C20: Marcos Roco Graccho | D20: 160125657 | E20: Descontos | F20: 400 | I20: Balança | J20: =TEXT(B20,"MM/YYYY") -> 01/2025 | K20: =IF(B20="","",CONCATENATE("CXG-",TEXT(B20,"MMYY"))) -> CXG-0125
A21: f63824f3 | B21: 45677 | C21: Marcos Roco Graccho | D21: 160125657 | E21: Descontos | F21: 200 | I21: Extratora | J21: =TEXT(B21,"MM/YYYY") -> 01/2025 | K21: =IF(B21="","",CONCATENATE("CXG-",TEXT(B21,"MMYY"))) -> CXG-0125
A22: 805452bf | B22: 45677 | C22: José Nunes | D22: 170125967 | E22: Descontos | F22: 500 | I22: Balança | J22: =TEXT(B22,"MM/YYYY") -> 01/2025 | K22: =IF(B22="","",CONCATENATE("CXG-",TEXT(B22,"MMYY"))) -> CXG-0125
A23: 90ace94d | B23: 45677 | C23: Edenilson Balsas | D23: 200125137 | E23: S.Grão - Sicredi | F23: 50000 | J23: =TEXT(B23,"MM/YYYY") -> 01/2025 | K23: =IF(B23="","",CONCATENATE("CXG-",TEXT(B23,"MMYY"))) -> CXG-0125
A24: 985daef3 | B24: 45677 | C24: Edenilson Balsas | D24: 200125137 | E24: S.Grão - Sicredi | F24: 28848 | J24: =TEXT(B24,"MM/YYYY") -> 01/2025 | K24: =IF(B24="","",CONCATENATE("CXG-",TEXT(B24,"MMYY"))) -> CXG-0125
A25: 7813d987 | B25: 45677 | C25: Abrel | D25: 1701251261 | E25: S.Grão - Sicredi | F25: 56886 | J25: =TEXT(B25,"MM/YYYY") -> 01/2025 | K25: =IF(B25="","",CONCATENATE("CXG-",TEXT(B25,"MMYY"))) -> CXG-0125
A26: 79200aa7 | B26: 45677 | C26: Abrel | D26: 1701251261 | E26: Descontos | F26: 0.9 | J26: =TEXT(B26,"MM/YYYY") -> 01/2025 | K26: =IF(B26="","",CONCATENATE("CXG-",TEXT(B26,"MMYY"))) -> CXG-0125
A27: 262cc249 | B27: 45677 | C27: Marcos Roco Graccho | D27: 160125657 | E27: S.Grão - Sicredi | F27: 150000 | J27: =TEXT(B27,"MM/YYYY") -> 01/2025 | K27: =IF(B27="","",CONCATENATE("CXG-",TEXT(B27,"MMYY"))) -> CXG-0125
A28: be270f32 | B28: 45677 | C28: Gabriel Balsas - Gilmar | D28: 1701251075 | E28: S.Grão - Sicredi | F28: 150000 | J28: =TEXT(B28,"MM/YYYY") -> 01/2025 | K28: =IF(B28="","",CONCATENATE("CXG-",TEXT(B28,"MMYY"))) -> CXG-0125
A29: 6f333624 | B29: 45677 | C29: Marcos Roco Graccho | D29: 160125657 | E29: S.Grão - Sicredi | F29: 90000 | J29: =TEXT(B29,"MM/YYYY") -> 01/2025 | K29: =IF(B29="","",CONCATENATE("CXG-",TEXT(B29,"MMYY"))) -> CXG-0125
A30: 2d67d5fb | B30: 45677 | C30: Milho Conde | D30: 2001251545 | E30: N.Nordeste - B.Brasil | F30: 140000 | J30: =TEXT(B30,"MM/YYYY") -> 01/2025 | K30: =IF(B30="","",CONCATENATE("CXG-",TEXT(B30,"MMYY"))) -> CXG-0125
A31: f96843ad | B31: 45678 | C31: Gabriel Balsas - Gilmar | D31: 1701251075 | E31: Descontos | F31: 463 | J31: =TEXT(B31,"MM/YYYY") -> 01/2025 | K31: =IF(B31="","",CONCATENATE("CXG-",TEXT(B31,"MMYY"))) -> CXG-0125
A32: 54cfbd21 | B32: 45679 | C32: Kelly Itabaianinha | D32: 160125470 | E32: Descontos | F32: 0.7 | J32: =TEXT(B32,"MM/YYYY") -> 01/2025 | K32: =IF(B32="","",CONCATENATE("CXG-",TEXT(B32,"MMYY"))) -> CXG-0125
A33: 8260c2ce | B33: 45679 | C33: Edenilson Balsas | D33: 200125137 | E33: N.Nordeste - B.Brasil | F33: 1192.25 | J33: =TEXT(B33,"MM/YYYY") -> 01/2025 | K33: =IF(B33="","",CONCATENATE("CXG-",TEXT(B33,"MMYY"))) -> CXG-0125
A34: 1fdfc2c6 | B34: 45679 | C34: José Nunes | D34: 170125967 | E34: S.Grão - Bradesco | F34: 215898 | J34: =TEXT(B34,"MM/YYYY") -> 01/2025 | K34: =IF(B34="","",CONCATENATE("CXG-",TEXT(B34,"MMYY"))) -> CXG-0125
A35: b3d8c0a7 | B35: 45679 | C35: José Nunes | D35: 170125967 | E35: Descontos | F35: 0.23 | J35: =TEXT(B35,"MM/YYYY") -> 01/2025 | K35: =IF(B35="","",CONCATENATE("CXG-",TEXT(B35,"MMYY"))) -> CXG-0125
A36: 3901d5f0 | B36: 45679 | C36: Samuel | D36: 2201251666 | E36: N.Nordeste - B.Brasil | F36: 700 | I36: Extratora | J36: =TEXT(B36,"MM/YYYY") -> 01/2025 | K36: =IF(B36="","",CONCATENATE("CXG-",TEXT(B36,"MMYY"))) -> CXG-0125
A37: 6290b1fb | B37: 45679 | C37: Francisco Benjamin | D37: 160125346 | E37: Santiagro | F37: 45071.66 | J37: =TEXT(B37,"MM/YYYY") -> 01/2025 | K37: =IF(B37="","",CONCATENATE("CXG-",TEXT(B37,"MMYY"))) -> CXG-0125
A38: 9474cee6 | B38: 45679 | C38: Gabriel Balsas/Irineu | D38: 2001251462 | E38: N.Nordeste - B.Brasil | F38: 300000 | J38: =TEXT(B38,"MM/YYYY") -> 01/2025 | K38: =IF(B38="","",CONCATENATE("CXG-",TEXT(B38,"MMYY"))) -> CXG-0125
A39: 34161587 | B39: 45680 | C39: Milho Conde | D39: 2001251545 | E39: N.Nordeste - B.Brasil | F39: 9000 | J39: =TEXT(B39,"MM/YYYY") -> 01/2025 | K39: =IF(B39="","",CONCATENATE("CXG-",TEXT(B39,"MMYY"))) -> CXG-0125
A40: a24494bb | B40: 45680 | C40: Kelly Itabaianinha | D40: 160125470 | E40: N.Nordeste - B.Brasil | F40: 150000 | J40: =TEXT(B40,"MM/YYYY") -> 01/2025 | K40: =IF(B40="","",CONCATENATE("CXG-",TEXT(B40,"MMYY"))) -> CXG-0125
...

Sheet PedComissão
A1: ID | B1: Data | C1: Parceiro | D1: PedidodeCompra | E1: Valor | F1: Valor Pago | G1: Valor Pendente | H1: Anotações | I1: PedComissao | J1: MesAno | K1: PedCxMensal
A2: 031ffa5f | B2: 45673 | C2: Gabriel Balsas | D2: 160125786 | E2: 1017.83 | F2: =SUMIFS(PagComisao!F:F,PagComisao!C:C,I:I) -> 1017.83 | G2: =E2-F2 -> 0 | I2: 160125218 | J2: =TEXT(B2,"MM/YYYY") -> 01/2025 | K2: =IF(B2="","",CONCATENATE("CXG-",TEXT(B2,"MMYY"))) -> CXG-0125
A3: 1b38353a | B3: 45671 | C3: Gabriel Balsas | D3: 170125830 | E3: 2370.5 | F3: =SUMIFS(PagComisao!F:F,PagComisao!C:C,I:I) -> 2370.5 | G3: =E3-F3 -> 0 | H3: Descontos Comprovante de 5 Mil da Implantação | I3: 170125334 | J3: =TEXT(B3,"MM/YYYY") -> 01/2025 | K3: =IF(B3="","",CONCATENATE("CXG-",TEXT(B3,"MMYY"))) -> CXG-0125
A4: 16948693 | B4: 45678 | C4: Gabriel Balsas | D4: 2001251462 | E4: 2427.39 | F4: =SUMIFS(PagComisao!F:F,PagComisao!C:C,I:I) -> 2427.39 | G4: =E4-F4 -> 0 | H4: Comprovante 3.122,09 | I4: 220125446 | J4: =TEXT(B4,"MM/YYYY") -> 01/2025 | K4: =IF(B4="","",CONCATENATE("CXG-",TEXT(B4,"MMYY"))) -> CXG-0125
A5: 5a09db25 | B5: 45678 | C5: Gabriel Balsas | D5: 1701251075 | E5: 694.7 | F5: =SUMIFS(PagComisao!F:F,PagComisao!C:C,I:I) -> 694.7 | G5: =E5-F5 -> 0 | H5: Comprovante 3.122,09 | I5: 220125578 | J5: =TEXT(B5,"MM/YYYY") -> 01/2025 | K5: =IF(B5="","",CONCATENATE("CXG-",TEXT(B5,"MMYY"))) -> CXG-0125
A6: eebc0e78 | B6: 45684 | C6: Gabriel Balsas | D6: 2001251462 | E6: 1334.09 | F6: =SUMIFS(PagComisao!F:F,PagComisao!C:C,I:I) -> 1334.09 | G6: =E6-F6 -> 0 | I6: 280125623 | J6: =TEXT(B6,"MM/YYYY") -> 01/2025 | K6: =IF(B6="","",CONCATENATE("CXG-",TEXT(B6,"MMYY"))) -> CXG-0125
A7: dc56a0ca | B7: 45684 | C7: Gabriel Balsas | D7: 1701251075 | E7: 259.2 | F7: =SUMIFS(PagComisao!F:F,PagComisao!C:C,I:I) -> 259.2 | G7: =E7-F7 -> 0 | I7: 280125714 | J7: =TEXT(B7,"MM/YYYY") -> 01/2025 | K7: =IF(B7="","",CONCATENATE("CXG-",TEXT(B7,"MMYY"))) -> CXG-0125
A8: d7738f85 | B8: 45691 | C8: Gabriel Balsas | D8: 1701251075 | E8: 1016.9 | F8: =SUMIFS(PagComisao!F:F,PagComisao!C:C,I:I) -> 1016.9 | G8: =E8-F8 -> 0 | I8: 030225850 | J8: =TEXT(B8,"MM/YYYY") -> 02/2025 | K8: =IF(B8="","",CONCATENATE("CXG-",TEXT(B8,"MMYY"))) -> CXG-0225
A9: d40643b3 | B9: 45692 | C9: Gabriel Balsas | D9: 1701251075 | E9: 919.6 | F9: =SUMIFS(PagComisao!F:F,PagComisao!C:C,I:I) -> 919.6 | G9: =E9-F9 -> 0 | H9: Carros: Rogerio, Carlos Aguiar e Douglas | I9: 040225998 | J9: =TEXT(B9,"MM/YYYY") -> 02/2025 | K9: =IF(B9="","",CONCATENATE("CXG-",TEXT(B9,"MMYY"))) -> CXG-0225
A10: f0f27a42 | B10: 45699 | C10: Gabriel Balsas | D10: 0502252287 | E10: 1173.85 | F10: =SUMIFS(PagComisao!F:F,PagComisao!C:C,I:I) -> 1173.85 | G10: =E10-F10 -> 0 | H10: Jonh e Regivaldo | I10: 1202251081 | J10: =TEXT(B10,"MM/YYYY") -> 02/2025 | K10: =IF(B10="","",CONCATENATE("CXG-",TEXT(B10,"MMYY"))) -> CXG-0225
A11: 5a6e4c1c | B11: 45701 | C11: Gabriel Balsas | D11: 1302252597 | E11: 1478.05 | F11: 1478.05 | G11: =E11-F11 -> 0 | H11: 3 Carros, Gustavo, Heder e Pereirinha. | I11: 1302251195 | J11: =TEXT(B11,"MM/YYYY") -> 02/2025 | K11: =IF(B11="","",CONCATENATE("CXG-",TEXT(B11,"MMYY"))) -> CXG-0225
A12: be8b61ae | B12: 45709 | C12: Guilherme | D12: 1302252597 | E12: 1840.33 | F12: =SUMIFS(PagComisao!F:F,PagComisao!C:C,I:I) -> 1840.33 | G12: =E12-F12 -> 0 | I12: 2402251240 | J12: =TEXT(B12,"MM/YYYY") -> 02/2025 | K12: =IF(B12="","",CONCATENATE("CXG-",TEXT(B12,"MMYY"))) -> CXG-0225
A13: 55a7f0b5 | B13: 45734 | C13: Gabriel Balsas | D13: 1003253656 | E13: 1887.69 | F13: =SUMIFS(PagComisao!F:F,PagComisao!C:C,I:I) -> 1887.69 | G13: =E13-F13 -> 0 | H13: Comissão Até o Carro de Valtemir - CX | I13: 1803251329 | J13: =TEXT(B13,"MM/YYYY") -> 03/2025 | K13: =IF(B13="","",CONCATENATE("CXG-",TEXT(B13,"MMYY"))) -> CXG-0325
A14: e7ebc9f7 | B14: 45734 | C14: Gabriel Balsas | D14: 1003253515 | E14: 4624.08 | F14: =SUMIFS(PagComisao!F:F,PagComisao!C:C,I:I) -> 4624.08 | G14: =E14-F14 -> 0 | H14: Comissão Até o Carro Andson Paiva | I14: 1803251492 | J14: =TEXT(B14,"MM/YYYY") -> 03/2025 | K14: =IF(B14="","",CONCATENATE("CXG-",TEXT(B14,"MMYY"))) -> CXG-0325
A15: 2092b041 | B15: 45782 | C15: Guilherme | D15: 0505255299 | E15: 2000 | F15: =SUMIFS(PagComisao!F:F,PagComisao!C:C,I:I) -> 2000 | G15: =E15-F15 -> 0 | I15: 0705251587 | J15: =TEXT(B15,"MM/YYYY") -> 05/2025 | K15: =IF(B15="","",CONCATENATE("CXG-",TEXT(B15,"MMYY"))) -> CXG-0525
A16: 79d6da61 | B16: 45785 | C16: Guilherme | D16: 0505255299 | E16: 1000 | F16: =SUMIFS(PagComisao!F:F,PagComisao!C:C,I:I) -> 1000 | G16: =E16-F16 -> 0 | I16: 0905251662 | J16: =TEXT(B16,"MM/YYYY") -> 05/2025 | K16: =IF(B16="","",CONCATENATE("CXG-",TEXT(B16,"MMYY"))) -> CXG-0525
A17: 445d10d6 | B17: 45790 | C17: Gabriel Balsas | D17: 1205255544 | E17: 586 | F17: =SUMIFS(PagComisao!F:F,PagComisao!C:C,I:I) -> 586 | G17: =E17-F17 -> 0 | I17: 1405251713 | J17: =TEXT(B17,"MM/YYYY") -> 05/2025 | K17: =IF(B17="","",CONCATENATE("CXG-",TEXT(B17,"MMYY"))) -> CXG-0525
E20: 0 | F20: =SUMIFS(PagComisao!F:F,PagComisao!C:C,I:I) -> 0 | G20: =E20-F20 -> 0 | J20: =TEXT(B20,"MM/YYYY") -> 12/1899 | K20: =IF(B20="","",CONCATENATE("CXG-",TEXT(B20,"MMYY")))
E21: 0 | F21: =SUMIFS(PagComisao!F:F,PagComisao!C:C,I:I) -> 0 | G21: =E21-F21 -> 0 | J21: =TEXT(B21,"MM/YYYY") -> 12/1899 | K21: =IF(B21="","",CONCATENATE("CXG-",TEXT(B21,"MMYY")))
E22: 0 | F22: =SUMIFS(PagComisao!F:F,PagComisao!C:C,I:I) -> 0 | G22: =E22-F22 -> 0 | J22: =TEXT(B22,"MM/YYYY") -> 12/1899 | K22: =IF(B22="","",CONCATENATE("CXG-",TEXT(B22,"MMYY")))
E23: 0 | F23: =SUMIFS(PagComisao!F:F,PagComisao!C:C,I:I) -> 0 | G23: =E23-F23 -> 0 | J23: =TEXT(B23,"MM/YYYY") -> 12/1899 | K23: =IF(B23="","",CONCATENATE("CXG-",TEXT(B23,"MMYY")))
E24: 0 | F24: =SUMIFS(PagComisao!F:F,PagComisao!C:C,I:I) -> 0 | G24: =E24-F24 -> 0 | J24: =TEXT(B24,"MM/YYYY") -> 12/1899 | K24: =IF(B24="","",CONCATENATE("CXG-",TEXT(B24,"MMYY")))
E25: 0 | F25: =SUMIFS(PagComisao!F:F,PagComisao!C:C,I:I) -> 0 | G25: =E25-F25 -> 0 | J25: =TEXT(B25,"MM/YYYY") -> 12/1899 | K25: =IF(B25="","",CONCATENATE("CXG-",TEXT(B25,"MMYY")))
E26: 0 | F26: =SUMIFS(PagComisao!F:F,PagComisao!C:C,I:I) -> 0 | G26: =E26-F26 -> 0 | J26: =TEXT(B26,"MM/YYYY") -> 12/1899 | K26: =IF(B26="","",CONCATENATE("CXG-",TEXT(B26,"MMYY")))
E27: 0 | F27: =SUMIFS(PagComisao!F:F,PagComisao!C:C,I:I) -> 0 | G27: =E27-F27 -> 0 | J27: =TEXT(B27,"MM/YYYY") -> 12/1899 | K27: =IF(B27="","",CONCATENATE("CXG-",TEXT(B27,"MMYY")))
E28: 0 | F28: =SUMIFS(PagComisao!F:F,PagComisao!C:C,I:I) -> 0 | G28: =E28-F28 -> 0 | J28: =TEXT(B28,"MM/YYYY") -> 12/1899 | K28: =IF(B28="","",CONCATENATE("CXG-",TEXT(B28,"MMYY")))
E29: 0 | F29: =SUMIFS(PagComisao!F:F,PagComisao!C:C,I:I) -> 0 | G29: =E29-F29 -> 0 | J29: =TEXT(B29,"MM/YYYY") -> 12/1899 | K29: =IF(B29="","",CONCATENATE("CXG-",TEXT(B29,"MMYY")))
E30: 0 | F30: =SUMIFS(PagComisao!F:F,PagComisao!C:C,I:I) -> 0 | G30: =E30-F30 -> 0 | J30: =TEXT(B30,"MM/YYYY") -> 12/1899 | K30: =IF(B30="","",CONCATENATE("CXG-",TEXT(B30,"MMYY")))
E31: 0 | F31: =SUMIFS(PagComisao!F:F,PagComisao!C:C,I:I) -> 0 | G31: =E31-F31 -> 0 | J31: =TEXT(B31,"MM/YYYY") -> 12/1899 | K31: =IF(B31="","",CONCATENATE("CXG-",TEXT(B31,"MMYY")))

Sheet PagComisao
A1: id | B1: data | C1: PedComissao | D1: Parceiro | E1: Conta | F1: Valor | G1: Anexo | H1: Foto | I1: MesAno | J1: PedCxMensal | K1: PedidodeCompra
A2: ee8b648e | B2: 45673 | C2: 160125218 | D2: Gabriel Balsas | E2: Neto - B.Brasil | F2: 1017.83 | I2: =TEXT(B2,"MM/YYYY") -> 01/2025 | J2: =IF(B2="","",CONCATENATE("CXG-",TEXT(B2,"MMYY"))) -> CXG-0125 | K2: 160125786
A3: f43c7bf8 | B3: 45673 | C3: 170125334 | D3: Gabriel Balsas | E3: Neto - B.Brasil | F3: 305 | I3: =TEXT(B3,"MM/YYYY") -> 01/2025 | J3: =IF(B3="","",CONCATENATE("CXG-",TEXT(B3,"MMYY"))) -> CXG-0125 | K3: 170125830
A4: d6e667b2 | B4: 45671 | C4: 170125334 | D4: Gabriel Balsas | E4: Descontos | F4: 2065.5 | I4: =TEXT(B4,"MM/YYYY") -> 01/2025 | J4: =IF(B4="","",CONCATENATE("CXG-",TEXT(B4,"MMYY"))) -> CXG-0125 | K4: 170125830
A5: d649a8ed | B5: 45678 | C5: 220125578 | D5: Gabriel Balsas | E5: S.Grão - Sicredi | F5: 694.7 | I5: =TEXT(B5,"MM/YYYY") -> 01/2025 | J5: =IF(B5="","",CONCATENATE("CXG-",TEXT(B5,"MMYY"))) -> CXG-0125 | K5: 1701251075
A6: a90cdcf7 | B6: 45678 | C6: 220125446 | D6: Gabriel Balsas | E6: S.Grão - Sicredi | F6: 2427.39 | I6: =TEXT(B6,"MM/YYYY") -> 01/2025 | J6: =IF(B6="","",CONCATENATE("CXG-",TEXT(B6,"MMYY"))) -> CXG-0125 | K6: 2001251462
A7: 27c9a609 | B7: 45685 | C7: 280125623 | D7: Gabriel Balsas | E7: S.Grão - Sicredi | F7: 1334.09 | I7: =TEXT(B7,"MM/YYYY") -> 01/2025 | J7: =IF(B7="","",CONCATENATE("CXG-",TEXT(B7,"MMYY"))) -> CXG-0125 | K7: 2001251462
A8: e625a00f | B8: 45684 | C8: 280125714 | D8: Gabriel Balsas | E8: S.Grão - Sicredi | F8: 259.2 | I8: =TEXT(B8,"MM/YYYY") -> 01/2025 | J8: =IF(B8="","",CONCATENATE("CXG-",TEXT(B8,"MMYY"))) -> CXG-0125 | K8: 1701251075
A9: dedc966a | B9: 45695 | C9: 040225998 | D9: Gabriel Balsas | E9: N.Nordeste - B.Brasil | F9: 919.6 | I9: =TEXT(B9,"MM/YYYY") -> 02/2025 | J9: =IF(B9="","",CONCATENATE("CXG-",TEXT(B9,"MMYY"))) -> CXG-0225 | K9: 1701251075
A10: 3686c105 | B10: 45695 | C10: 030225850 | D10: Gabriel Balsas | E10: N.Nordeste - B.Brasil | F10: 1016.9 | I10: =TEXT(B10,"MM/YYYY") -> 02/2025 | J10: =IF(B10="","",CONCATENATE("CXG-",TEXT(B10,"MMYY"))) -> CXG-0225 | K10: 1701251075
A11: 34040aba | B11: 45702 | C11: 1202251081 | D11: Gabriel Balsas | E11: N.Nordeste - B.Brasil | F11: 1173.85 | I11: =TEXT(B11,"MM/YYYY") -> 02/2025 | J11: =IF(B11="","",CONCATENATE("CXG-",TEXT(B11,"MMYY"))) -> CXG-0225 | K11: 0502252287
A12: 7ee3b325 | B12: 45709 | C12: 2402251240 | D12: Guilherme | E12: S.Grão - Sicredi | F12: 1840.33 | I12: =TEXT(B12,"MM/YYYY") -> 02/2025 | J12: =IF(B12="","",CONCATENATE("CXG-",TEXT(B12,"MMYY"))) -> CXG-0225 | K12: 1302252597
A13: df4c9cb0 | B13: 45735 | C13: 1803251329 | D13: Gabriel Balsas | E13: S.Grão - Sicredi | F13: 1887.69 | I13: =TEXT(B13,"MM/YYYY") -> 03/2025 | J13: =IF(B13="","",CONCATENATE("CXG-",TEXT(B13,"MMYY"))) -> CXG-0325 | K13: 1003253656
... A17: f7bb4631 | B17: 45790 | C17: 1405251713 | D17: Gabriel Balsas | E17: N.Nordeste - B.Brasil | F17: 586 | I17: =TEXT(B17,"MM/YYYY") -> 05/2025 | J17: =IF(B17="","",CONCATENATE("CXG-",TEXT(B17,"MMYY"))) -> CXG-0525 | K17: 1205255544
C18: 1302252597
I20: =TEXT(B20,"MM/YYYY") -> 12/1899 | J20: =IF(B20="","",CONCATENATE("CXG-",TEXT(B20,"MMYY")))
I21: =TEXT(B21,"MM/YYYY") -> 12/1899 | J21: =IF(B21="","",CONCATENATE("CXG-",TEXT(B21,"MMYY")))
I22: =TEXT(B22,"MM/YYYY") -> 12/1899 | J22: =IF(B22="","",CONCATENATE("CXG-",TEXT(B22,"MMYY")))
I23: =TEXT(B23,"MM/YYYY") -> 12/1899 | J23: =IF(B23="","",CONCATENATE("CXG-",TEXT(B23,"MMYY")))
I24: =TEXT(B24,"MM/YYYY") -> 12/1899 | J24: =IF(B24="","",CONCATENATE("CXG-",TEXT(B24,"MMYY")))
I25: =TEXT(B25,"MM/YYYY") -> 12/1899 | J25: =IF(B25="","",CONCATENATE("CXG-",TEXT(B25,"MMYY")))
I26: =TEXT(B26,"MM/YYYY") -> 12/1899 | J26: =IF(B26="","",CONCATENATE("CXG-",TEXT(B26,"MMYY")))
I27: =TEXT(B27,"MM/YYYY") -> 12/1899 | J27: =IF(B27="","",CONCATENATE("CXG-",TEXT(B27,"MMYY")))
I28: =TEXT(B28,"MM/YYYY") -> 12/1899 | J28: =IF(B28="","",CONCATENATE("CXG-",TEXT(B28,"MMYY")))
I29: =TEXT(B29,"MM/YYYY") -> 12/1899 | J29: =IF(B29="","",CONCATENATE("CXG-",TEXT(B29,"MMYY")))
I30: =TEXT(B30,"MM/YYYY") -> 12/1899 | J30: =IF(B30="","",CONCATENATE("CXG-",TEXT(B30,"MMYY")))
I31: =TEXT(B31,"MM/YYYY") -> 12/1899 | J31: =IF(B31="","",CONCATENATE("CXG-",TEXT(B31,"MMYY")))
I32: =TEXT(B32,"MM/YYYY") -> 12/1899 | J32: =IF(B32="","",CONCATENATE("CXG-",TEXT(B32,"MMYY")))

Sheet PedFretes
A1: id | B1: Data | C1: PedidodeCompra | D1: PedidoFrete | E1: ValorTotal | F1: ValorPago | G1: ValorPendente | H1: Anotações | I1: Gatilho | J1: MesAno | K1: PedCxMensal | L1: Despesas Extras | M1: Transportadora | N1: Observações
A2: 4b2260c0 | B2: 45672 | D2: TW15012521 | E2: =SUMIFS(CarrinhoFretes!L:L,CarrinhoFretes!C:C,D:D) -> 326549.7 | F2: =SUMIFS(PagFretes!E:E,PagFretes!C:C,D:D)+(SUMIFS(PagFreteIndividal!E:E, PagFreteIndividal!H:H, D:D, PagFreteIndividal!F:F, "<>Adiantamento") ) -> 326549.7 | G2: =E2-F2 -> 0 | H2: Finalizado | I2: 46017.454 | J2: =TEXT(B2,"MM/YYYY") -> 01/2025 | K2: =IF(B2="","",CONCATENATE("CXG-",TEXT(B2,"MMYY"))) -> CXG-0125 | L2: =SUMIFS(DesExtFrete!F:F,DesExtFrete!C:C,D:D) -> 160 | M2: TW - Suporte Agrícola | N2: Janeiro
A3: 075f1185 | B3: 45673 | D3: SR16012556 | E3: =SUMIFS(CarrinhoFretes!L:L,CarrinhoFretes!C:C,D:D) -> 151885.9 | F3: =SUMIFS(PagFretes!E:E,PagFretes!C:C,D:D)+(SUMIFS(PagFreteIndividal!E:E, PagFreteIndividal!H:H, D:D, PagFreteIndividal!F:F, "<>Adiantamento") ) -> 151885.9 | G3: =E3-F3 -> 0 | H3: Finalizado | I3: 45687.607 | J3: =TEXT(B3,"MM/YYYY") -> 01/2025 | K3: =IF(B3="","",CONCATENATE("CXG-",TEXT(B3,"MMYY"))) -> CXG-0125 | L3: =SUMIFS(DesExtFrete!F:F,DesExtFrete!C:C,D:D) -> 0 | M3: SR - Sergio Rocha
F4: =SUMIFS(PagFretes!E:E,PagFretes!C:C,D:D)+(SUMIFS(PagFreteIndividal!E:E, PagFreteIndividal!H:H, D:D, PagFreteIndividal!F:F, "<>Adiantamento") ) -> 0
